---
title: "Effective Error Handling in Python: Try-Except Blocks and Finally Clause"
description: "Learn how to robustly handle errors in Python using try-except blocks and the finally clause. This guide explains the mechanisms behind Python's error handling, with detailed examples to help you write more reliable code."
icon: "code"
draft: false
---

## Introduction

Handling errors properly in a Python program is crucial to ensure that the program can gracefully handle unexpected situations without crashing. Python provides several ways to handle errors, most notably through try-except blocks and the finally clause.

### Try-Except Blocks

Try-except blocks are used to catch and handle exceptions. An exception is an event, which occurs during the execution of a program that disrupts the normal flow of the program's instructions.

#### Syntax and Explanation:
```python
try:
    # Code that might cause an exception
except ExceptionType:
    # Code that runs if an exception occurs
```

#### Example:
```python
try:
    # Potential error code
    result = 10 / 0
except ZeroDivisionError:
    # Handling the specific error
    print("You can't divide by zero!")
```
This example tries to perform division by zero, which raises a `ZeroDivisionError`. The except block catches this specific error and prints a custom error message.

### Extending Try-Except Blocks

You can also catch multiple exceptions in a single try-except block, and use else and finally clauses for additional functionality.

#### Example:
```python
try:
    num = int(input("Enter a number: "))
    inverse = 1 / num
except ValueError:
    print("That's not a valid number!")
except ZeroDivisionError:
    print("Infinity! Division by zero.")
else:
    print("The inverse is:", inverse)
finally:
    print("This block always executes, regardless of any exceptions.")
```
In this detailed example:
- The `ValueError` is caught if the input is not a valid integer.
- The `ZeroDivisionError` is caught if the number is zero.
- The `else` block runs if no exceptions are raised.
- The `finally` clause executes after all the other parts of the try-except block, regardless of whether an exception was raised or not. It is useful for clean-up actions that must be executed under all circumstances.

### Finally Clause

The finally clause is an optional block that, if specified, will execute as the last task before the try statement completes. The finally block runs whether or not an exception is caught.

#### Example:
```python
try:
    f = open('file.txt')
    data = f.read()
    print(data)
except FileNotFoundError:
    print("File not found.")
finally:
    f.close()
    print("File closed.")
```
This example attempts to open and read a file. If the file does not exist, a `FileNotFoundError` is raised and handled. The `finally` block ensures that the file is closed after attempting to read it, whether the file was successfully opened or not.

### Conclusion

Proper error handling is an essential aspect of developing robust Python applications. By understanding and implementing try-except blocks and the finally clause, you can prevent your programs from crashing unexpectedly and ensure they execute more reliably.
